Workbook

Sheet Instruções
A1: EDAV-AL — Planilha de Validade de Conteúdo (CVC) para avaliação por juízes
A2: Legenda: células com fundo amarelo e texto azul são as únicas que devem ser preenchidas/editadas.
A4: Parâmetro | B4: Valor | C4: Observação
A5: Nº de juízes (J) | B5: 5 | C5: Número definido no grupo (5 juízes). As colunas da aba de avaliação têm J1–J5; não altere sem ajustar as colunas.
A6: Nota máxima (Vmax) | B6: 5 | C6: Escala Likert de 1 a 5.
A7: Erro por viés de juízes (Pe) | B7: =(1/B5)^B5 -> 0.00032 | C7: Fórmula: Pe = (1/J)^J.
A8: Ponto de corte — Manter (≥) | B8: 0.8 | C8: Corte usual na literatura brasileira atribuído a Hernández-Nieto (2002); confirme com o critério adotado pela professora.
A9: Ponto de corte — Revisar (≥) | B9: 0.7 | C9: Abaixo desse valor o item é marcado como 'Descartar'. Valor de referência, ajustável.
A11: Como preencher (juízes)
A12: 1. Abra a aba 'Avaliação CVC'. Os itens estão agrupados por dimensão (D1 a D5), com o código, a origem e as versões em que aparecem.
A13: 2. Para cada item, dê uma nota de 1 a 5 em cada um dos três critérios, na coluna do seu juiz (J1 a J5).
A14: 3. Escala: 1 = pouquíssimo · 2 = pouco · 3 = médio · 4 = muito · 5 = muitíssimo.
A15: 4. Se der nota 3 ou menos, descreva o problema/sugestão na coluna 'Observações'.
A16: 5. As colunas de CVC e a decisão só aparecem quando os 5 juízes tiverem avaliado o item nos 3 critérios.
A18: Critérios avaliados
A19: Critério | C19: O que o juiz avalia
A20: Clareza de linguagem | C20: O item é compreensível e sem ambiguidade para o público-alvo (funcionários da UFMG)?
A21: Pertinência prática | C21: O item é adequado à realidade do trabalho dos funcionários da UFMG (docentes, TAEs e terceirizados)?
A22: Relevância teórica | C22: O item representa bem a dimensão em que foi classificado?
A24: Como o CVC é calculado
A25: CVC do critério = (média das notas dos 5 juízes ÷ Vmax) − Pe.
A26: CVC do item = média dos CVC dos 3 critérios. CVC da dimensão = média do CVC dos itens avaliados (aba 'Resumo').
A27: Decisão: Manter (≥ corte de manter) · Revisar (≥ corte de revisar) · Descartar (abaixo). Cortes editáveis nos parâmetros acima.
A29: Juízes (opcional: escreva os nomes)
A30: J1
A31: J2
A32: J3
A33: J4
A34: J5
A36: Exemplo de preenchimento (item fictício, apenas ilustrativo — não entra nos cálculos)
A37: Critério | B37: Notas J1 a J5 | C37: CVC do critério (fórmula)
A38: Clareza de linguagem | B38: 5 · 4 · 5 · 5 · 4 | C38: =ROUND(AVERAGE(5,4,5,5,4)/$B$6-$B$7,4) -> 0.9197
A39: Pertinência prática | B39: 4 · 4 · 5 · 4 · 4 | C39: =ROUND(AVERAGE(4,4,5,4,4)/$B$6-$B$7,4) -> 0.8397
A40: Relevância teórica | B40: 5 · 5 · 4 · 5 · 5 | C40: =ROUND(AVERAGE(5,5,4,5,5)/$B$6-$B$7,4) -> 0.9597
A41: CVC do item (exemplo) | C41: =ROUND(AVERAGE(C38:C40),4) -> 0.9064
A42: Decisão (exemplo) | C42: =IF(C41>=$B$8,"Manter",IF(C41>=$B$9,"Revisar","Descartar")) -> Manter

Sheet Guia Como votar
A1: EDAV-AL — Guia do juiz: como votar
A2: Leia esta aba antes de preencher. Você vai dar notas de 1 a 5 para cada item da aba 'Avaliação CVC', em três critérios, usando apenas a coluna do seu juiz (J1 a J5).
A4: 1. Passo a passo
A5: Etapa | C5: O que fazer
A6: 1. Abra a aba 'Avaliação CVC' | C6: Os itens estão agrupados por dimensão (D1 a D5). Cada linha é um item, com código (ID), item-base, tipo, versões em que aparece e o texto do item.
A7: 2. Descubra qual é a sua coluna | C7: Você é J1, J2, J3, J4 ou J5. Cada critério tem cinco colunas, uma por juiz. Veja a tabela da seção 3 para achar as suas três colunas.
A8: 3. Leia o item com atenção | C8: Avalie o texto da linha, sem se influenciar pelas notas dos colegas. Variantes do mesmo item-base ficam juntas, mas cada linha deve receber a sua própria nota.
A9: 4. Dê três notas de 1 a 5 | C9: Uma nota para cada critério: clareza de linguagem, pertinência prática e relevância teórica. Só números inteiros de 1 a 5 são aceitos; qualquer outro valor é recusado pela planilha.
A10: 5. Explique notas baixas | C10: Se alguma nota for 3 ou menos, ela fica em vermelho e a célula 'Observações / sugestão de reformulação' (última coluna) fica laranja. Descreva o problema e, se puder, sugira uma nova redação.
A11: 6. Confira no final | C11: Todos os itens têm as três notas na sua coluna? As notas ≤ 3 têm observação? Não mexa nas colunas cinzas de CVC e Decisão: elas são calculadas sozinhas.
A13: 2. Escala de notas
A14: Nota | B14: Significado | D14: Leitura sugerida (para o critério que você está avaliando)
A15: 1 | B15: pouquíssimo | D15: O item praticamente não atende ao critério.
A16: 2 | B16: pouco | D16: O item atende só em pequena parte.
A17: 3 | B17: médio | D17: Atende de forma parcial; precisa de ajustes. Escreva uma observação.
A18: 4 | B18: muito | D18: Atende bem; pode haver pequenos ajustes.
A19: 5 | B19: muitíssimo | D19: Atende plenamente ao critério.
A20: Regra da planilha: nota 3 ou menor exige observação. A coluna de observações não entra nos cálculos, mas é o que permite ao grupo reformular o item.
A22: 3. Onde dar cada nota
A23: Critério | B23: O que você avalia | G23: Colunas (J1 a J5)
A24: Clareza de linguagem | B24: O item é compreensível e sem ambiguidade para o público-alvo (funcionários da UFMG)? | G24: H a L
A25: Pertinência prática | B25: O item é adequado à realidade do trabalho dos funcionários da UFMG (docentes, TAEs e terceirizados)? | G25: M a Q
A26: Relevância teórica | B26: O item representa bem a dimensão em que foi classificado? | G26: R a V
A28: Seu juiz | B28: Clareza | D28: Pertinência | F28: Relevância | H28: Nome (aba Instruções)
A29: J1 | B29: coluna H | D29: coluna M | F29: coluna R | H29: =IF(Instruções!$B$30="","",Instruções!$B$30)
A30: J2 | B30: coluna I | D30: coluna N | F30: coluna S | H30: =IF(Instruções!$B$31="","",Instruções!$B$31)
A31: J3 | B31: coluna J | D31: coluna O | F31: coluna T | H31: =IF(Instruções!$B$32="","",Instruções!$B$32)
A32: J4 | B32: coluna K | D32: coluna P | F32: coluna U | H32: =IF(Instruções!$B$33="","",Instruções!$B$33)
A33: J5 | B33: coluna L | D33: coluna Q | F33: coluna V | H33: =IF(Instruções!$B$34="","",Instruções!$B$34)
A34: As demais colunas da aba 'Avaliação CVC' (ID, Dim., Item-base, Tipo, Versões, Item) apenas identificam o item. As colunas W a AA (CVC e Decisão) são automáticas. A coluna AB é para as observações.
A36: 4. Como ler as informações do item
A37: Campo | B37: Significado
A38: ID | B38: Código único do item, no formato dimensão-número (ex.: D1-01).
A39: Dim. | B39: Dimensão em que o item foi classificado (D1 a D5).
A40: Item-base | B40: Código do item-base (B01, B02...). Itens com o mesmo código são versões do mesmo conteúdo; '—' indica item sem item-base.
A41: Tipo | B41: Item-base, variante do item-base ou item novo.
A42: Versões | B42: Versões do instrumento em que o item aparece (v1 a v5).
A44: 5. O que a planilha mostra de volta
A45: Nota ≤ 3 | B45: A célula fica em vermelho.
A46: Observação pendente | B46: A célula de observações fica laranja enquanto houver nota ≤ 3 sem comentário.
...

Sheet Guia Cálculos
A1: EDAV-AL — Guia dos cálculos do CVC
A2: O CVC (Coeficiente de Validade de Conteúdo) transforma as notas dos 5 juízes em um número entre 0 e 1 para cada critério, cada item e cada dimensão. Os valores desta aba vêm da aba 'Instruções' e acompanham qualquer ajuste feito lá.
A4: 1. Parâmetros usados nas contas
A5: Parâmetro | B5: Valor | C5: Observação
A6: Nº de juízes (J) | B6: =Instruções!$B$5 -> 5 | C6: Cinco juízes. As fórmulas da aba 'Avaliação CVC' usam as colunas J1 a J5.
A7: Nota máxima (Vmax) | B7: =Instruções!$B$6 -> 5 | C7: Escala Likert de 1 a 5.
A8: Erro por viés (Pe) | B8: =Instruções!$B$7 -> 0.00032 | C8: Pe = (1/J)^J. É o desconto aplicado a cada CVC de critério.
A9: Corte para Manter (≥) | B9: =Instruções!$B$8 -> 0.8 | C9: Corte usual na literatura brasileira, atribuído a Hernández-Nieto (2002). Confirme com o critério adotado pela professora.
A10: Corte para Revisar (≥) | B10: =Instruções!$B$9 -> 0.7 | C10: Abaixo desse valor o item é marcado como Descartar. Valor de referência, ajustável.
A11: Verde = valor puxado da aba 'Instruções'. Para mudar um parâmetro, altere-o lá.
A13: 2. O caminho do cálculo, em cinco etapas
A14: Etapa 1 — Média das notas de cada critério
A15: Onde | B15: Aba 'Avaliação CVC', dentro das colunas W, X e Y.
A16: Em palavras | B16: Soma as notas dos 5 juízes naquele critério e divide por 5. Se faltar alguma nota, o CVC do critério fica vazio.
A17: Fórmula (linha 7) | B17: AVERAGE(H7:L7) (clareza) · AVERAGE(M7:Q7) (pertinência) · AVERAGE(R7:V7) (relevância)
A19: Etapa 2 — CVC de cada critério (colunas W, X e Y)
A20: Onde | B20: Aba 'Avaliação CVC': W = clareza, X = pertinência, Y = relevância.
A21: Em palavras | B21: Divide a média pela nota máxima, o que coloca o resultado na escala de 0 a 1, e subtrai o erro por viés Pe. Só calcula quando os 5 juízes avaliaram.
A22: Fórmula (linha 7) | B22: =IF(COUNT(H7:L7)<Instruções!$B$5,"",AVERAGE(H7:L7)/Instruções!$B$6-Instruções!$B$7)
A24: Etapa 3 — CVC do item (coluna Z)
A25: Onde | B25: Aba 'Avaliação CVC', coluna Z.
A26: Em palavras | B26: Média simples dos três CVC de critério. Só aparece quando os três critérios já foram calculados.
A27: Fórmula (linha 7) | B27: =IF(OR(W7="",X7="",Y7=""),"",AVERAGE(W7:Y7))
A29: Etapa 4 — Decisão (coluna AA)
A30: Onde | B30: Aba 'Avaliação CVC', coluna AA.
A31: Em palavras | B31: Compara o CVC do item com os dois cortes: Manter se for igual ou maior que o corte de manter; Revisar se for igual ou maior que o corte de revisar; Descartar se ficar abaixo.
A32: Fórmula (linha 7) | B32: =IF(Z7="","",IF(Z7>=Instruções!$B$8,"Manter",IF(Z7>=Instruções!$B$9,"Revisar","Descartar")))
A34: Etapa 5 — CVC da dimensão (aba 'Resumo')
A35: Onde | B35: Aba 'Resumo', coluna G (e D, E, F para cada critério).
A36: Em palavras | B36: Média do CVC dos itens da dimensão que já têm CVC calculado. Itens ainda incompletos ficam de fora da média.
A37: Fórmula (linha 7) | B37: =IFERROR(AVERAGEIFS('Avaliação CVC'!$Z$6:$Z$165,'Avaliação CVC'!$B$6:$B$165,A4),"")
A39: 3. Exemplo passo a passo (item fictício, não entra nos cálculos)
A40: As contas abaixo são fórmulas reais ligadas aos parâmetros da seção 1. As notas em azul são só do exemplo; mudar essas células não afeta a avaliação.
A41: Critério | B41: J1 | C41: J2 | D41: J3 | E41: J4 | F41: J5 | G41: Média das notas | H41: Média ÷ Vmax | I41: CVC do critério
A42: Clareza de linguagem | B42: 4 | C42: 3 | D42: 4 | E42: 4 | F42: 3 | G42: =AVERAGE(B42:F42) -> 3.6 | H42: =G42/$B$7 -> 0.72 | I42: =H42-$B$8 -> 0.71968
A43: Pertinência prática | B43: 4 | C43: 4 | D43: 3 | E43: 4 | F43: 4 | G43: =AVERAGE(B43:F43) -> 3.8 | H43: =G43/$B$7 -> 0.76 | I43: =H43-$B$8 -> 0.75968
A44: Relevância teórica | B44: 5 | C44: 4 | D44: 4 | E44: 4 | F44: 4 | G44: =AVERAGE(B44:F44) -> 4.2 | H44: =G44/$B$7 -> 0.84 | I44: =H44-$B$8 -> 0.83968
A45: CVC do item = média dos 3 CVC de critério | I45: =AVERAGE(I42:I44) -> 0.77301333
A46: Decisão (compara com os cortes da seção 1) | I46: =IF($I$45>=$B$9,"Manter",IF($I$45>=$B$10,"Revisar","Descartar")) -> Revisar
A47: Neste exemplo, o item fica entre os dois cortes: não atinge o de manter, mas passa o de revisar. A decisão é Revisar: vale reformular o texto antes de decidir se o item permanece.
...

Sheet Dimensões
A1: Cód. | B1: Dimensão (nome do banco de itens) | C1: Definição | D1: Nome alternativo (versão neutra da justificativa) | E1: Nº de itens únicos | F1: Observação
A2: D1 | B2: Hipervigilância Social Racializada e Adaptativa | C2: Gasto de energia psíquica para antecipar episódios de discriminação. | D2: Carga de vigilância relacional e tensão interpessoal no trabalho | E2: =COUNTIF('Avaliação CVC'!$B$6:$B$175,A2) -> 36 | F2: Presente nas 5 versões (7 itens-base + novos).
A3: D2 | B3: Carga Mental de Transposição de Barreiras | C3: Desgaste decorrente de barreiras arquitetônicas, econômicas e comunicacionais. | D3: Desgaste operacional e carga de transposição de barreiras | E3: =COUNTIF('Avaliação CVC'!$B$6:$B$175,A3) -> 38 | F3: Presente nas 5 versões; na v2 todos os itens são novos.
A4: D3 | B4: Agência Comunitária e Rede de Cuidado Solidário | C4: Fatores de proteção e suporte social interpessoal no campus. | D4: Agência comunitária e rede de suporte institucional | E4: =COUNTIF('Avaliação CVC'!$B$6:$B$175,A4) -> 35 | F4: Presente nas 5 versões; itens de proteção.
A5: D4 | B5: Sentimento de Pertencimento e Desalienação do Espaço | C5: Impacto existencial e relação de inclusão/exclusão do sujeito com a instituição. | D5: Integração institucional e pertencimento no território laboral | E5: =COUNTIF('Avaliação CVC'!$B$6:$B$175,A5) -> 37 | F5: Presente nas 5 versões; itens de proteção.
A6: D5 | B6: Saúde Mental (dimensão proposta só na v2) | C6: RASCUNHO derivado dos itens (não consta nos documentos): condições de trabalho e suporte institucional para a preservação da saúde mental e do bem-estar do trabalhador. | D6: — (sem equivalente na versão neutra) | E6: =COUNTIF('Avaliação CVC'!$B$6:$B$175,A6) -> 9 | F6: Aparece apenas na v2. O grupo decidiu trabalhar com 4 dimensões: definir se D5 permanece, é absorvida por outra dimensão ou sai.
D7: Total | E7: =SUM(E2:E6) -> 155
A9: Nota: nomes e definições de D1–D4 vêm do documento do grupo; a definição de D5 é um rascunho para validação do grupo.

Sheet Avaliação CVC
A1: EDAV-AL — Avaliação dos itens pelos juízes (CVC)
A2: Notas de 1 a 5 nas células amarelas. Itens agrupados por dimensão; variantes do mesmo item-base ficam juntas. Instruções e cortes na aba 'Instruções'.
A3: Escala: 1 = pouquíssimo · 2 = pouco · 3 = médio · 4 = muito · 5 = muitíssimo | Nota ≤ 3 fica em vermelho: descreva o problema/sugestão em Observações (célula laranja até ser preenchida).
A4: ID | B4: Dim. | C4: Item-base | D4: Tipo | E4: Versões | F4: Item | H4: Clareza de linguagem | M4: Pertinência prática | R4: Relevância teórica | W4: CVC clareza | X4: CVC pertinência | Y4: CVC relevância | Z4: CVC do item | AA4: Decisão | AB4: Observações / sugestão de reformulação
H5: J1 | I5: J2 | J5: J3 | K5: J4 | L5: J5 | M5: J1 | N5: J2 | O5: J3 | P5: J4 | Q5: J5 | R5: J1 | S5: J2 | T5: J3 | U5: J4 | V5: J5
A6: D1 — Hipervigilância Social Racializada e Adaptativa Gasto de energia psíquica para antecipar episódios de discriminação.
A7: D1-01 | B7: D1 | C7: B01 | D7: Item-base | E7: v1, v5 | F7: Sinto que preciso prestar atenção dobrada no meu modo de falar ou vestir para evitar ser mal interpretado(a) ou discriminado(a) no campus. | W7: =IF(COUNT(H7:L7)<Instruções!$B$5,"",AVERAGE(H7:L7)/Instruções!$B$6-Instruções!$B$7) | X7: =IF(COUNT(M7:Q7)<Instruções!$B$5,"",AVERAGE(M7:Q7)/Instruções!$B$6-Instruções!$B$7) | Y7: =IF(COUNT(R7:V7)<Instruções!$B$5,"",AVERAGE(R7:V7)/Instruções!$B$6-Instruções!$B$7) | Z7: =IF(OR(W7="",X7="",Y7=""),"",AVERAGE(W7:Y7)) | AA7: =IF(Z7="","",IF(Z7>=Instruções!$B$8,"Manter",IF(Z7>=Instruções!$B$9,"Revisar","Descartar")))
A8: D1-02 | B8: D1 | C8: B01 | D8: Variante do item-base | E8: v2 | F8: Percebo a necessidade de monitorar meu modo de falar ou me comportar para evitar julgamentos ou interpretações distorcidas no trabalho. | W8: =IF(COUNT(H8:L8)<Instruções!$B$5,"",AVERAGE(H8:L8)/Instruções!$B$6-Instruções!$B$7) | X8: =IF(COUNT(M8:Q8)<Instruções!$B$5,"",AVERAGE(M8:Q8)/Instruções!$B$6-Instruções!$B$7) | Y8: =IF(COUNT(R8:V8)<Instruções!$B$5,"",AVERAGE(R8:V8)/Instruções!$B$6-Instruções!$B$7) | Z8: =IF(OR(W8="",X8="",Y8=""),"",AVERAGE(W8:Y8)) | AA8: =IF(Z8="","",IF(Z8>=Instruções!$B$8,"Manter",IF(Z8>=Instruções!$B$9,"Revisar","Descartar")))
A9: D1-03 | B9: D1 | C9: B01 | D9: Variante do item-base | E9: v3 | F9: Sinto que preciso redobrar a atenção no meu modo de falar, vestir ou agir para evitar ser mal interpretado(a) no trabalho. | W9: =IF(COUNT(H9:L9)<Instruções!$B$5,"",AVERAGE(H9:L9)/Instruções!$B$6-Instruções!$B$7) | X9: =IF(COUNT(M9:Q9)<Instruções!$B$5,"",AVERAGE(M9:Q9)/Instruções!$B$6-Instruções!$B$7) | Y9: =IF(COUNT(R9:V9)<Instruções!$B$5,"",AVERAGE(R9:V9)/Instruções!$B$6-Instruções!$B$7) | Z9: =IF(OR(W9="",X9="",Y9=""),"",AVERAGE(W9:Y9)) | AA9: =IF(Z9="","",IF(Z9>=Instruções!$B$8,"Manter",IF(Z9>=Instruções!$B$9,"Revisar","Descartar")))
A10: D1-04 | B10: D1 | C10: B01 | D10: Variante do item-base | E10: v4 | F10: Sinto que preciso prestar atenção na maneira como me comporto para evitar ser discriminado no ambiente de trabalho. | W10: =IF(COUNT(H10:L10)<Instruções!$B$5,"",AVERAGE(H10:L10)/Instruções!$B$6-Instruções!$B$7) | X10: =IF(COUNT(M10:Q10)<Instruções!$B$5,"",AVERAGE(M10:Q10)/Instruções!$B$6-Instruções!$B$7) | Y10: =IF(COUNT(R10:V10)<Instruções!$B$5,"",AVERAGE(R10:V10)/Instruções!$B$6-Instruções!$B$7) | Z10: =IF(OR(W10="",X10="",Y10=""),"",AVERAGE(W10:Y10)) | AA10: =IF(Z10="","",IF(Z10>=Instruções!$B$8,"Manter",IF(Z10>=Instruções!$B$9,"Revisar","Descartar")))
A11: D1-05 | B11: D1 | C11: B02 | D11: Item-base | E11: v1, v4, v5 | F11: Fico tenso(a) ou apreensivo(a) ao circular por determinados prédios ou espaços da universidade, onde vejo poucas pessoas com o meu perfil. | W11: =IF(COUNT(H11:L11)<Instruções!$B$5,"",AVERAGE(H11:L11)/Instruções!$B$6-Instruções!$B$7) | X11: =IF(COUNT(M11:Q11)<Instruções!$B$5,"",AVERAGE(M11:Q11)/Instruções!$B$6-Instruções!$B$7) | Y11: =IF(COUNT(R11:V11)<Instruções!$B$5,"",AVERAGE(R11:V11)/Instruções!$B$6-Instruções!$B$7) | Z11: =IF(OR(W11="",X11="",Y11=""),"",AVERAGE(W11:Y11)) | AA11: =IF(Z11="","",IF(Z11>=Instruções!$B$8,"Manter",IF(Z11>=Instruções!$B$9,"Revisar","Descartar")))
A12: D1-06 | B12: D1 | C12: B02 | D12: Variante do item-base | E12: v2 | F12: Adoto maior reserva ou cautela ao circular por determinados ambientes da universidade onde me sinto pouco integrado. | W12: =IF(COUNT(H12:L12)<Instruções!$B$5,"",AVERAGE(H12:L12)/Instruções!$B$6-Instruções!$B$7) | X12: =IF(COUNT(M12:Q12)<Instruções!$B$5,"",AVERAGE(M12:Q12)/Instruções!$B$6-Instruções!$B$7) | Y12: =IF(COUNT(R12:V12)<Instruções!$B$5,"",AVERAGE(R12:V12)/Instruções!$B$6-Instruções!$B$7) | Z12: =IF(OR(W12="",X12="",Y12=""),"",AVERAGE(W12:Y12)) | AA12: =IF(Z12="","",IF(Z12>=Instruções!$B$8,"Manter",IF(Z12>=Instruções!$B$9,"Revisar","Descartar")))
A13: D1-07 | B13: D1 | C13: B02 | D13: Variante do item-base | E13: v3 | F13: Sinto tensão ao circular por espaços da instituição em que ainda não me sinto familiarizado(a). | W13: =IF(COUNT(H13:L13)<Instruções!$B$5,"",AVERAGE(H13:L13)/Instruções!$B$6-Instruções!$B$7) | X13: =IF(COUNT(M13:Q13)<Instruções!$B$5,"",AVERAGE(M13:Q13)/Instruções!$B$6-Instruções!$B$7) | Y13: =IF(COUNT(R13:V13)<Instruções!$B$5,"",AVERAGE(R13:V13)/Instruções!$B$6-Instruções!$B$7) | Z13: =IF(OR(W13="",X13="",Y13=""),"",AVERAGE(W13:Y13)) | AA13: =IF(Z13="","",IF(Z13>=Instruções!$B$8,"Manter",IF(Z13>=Instruções!$B$9,"Revisar","Descartar")))
A14: D1-08 | B14: D1 | C14: B03 | D14: Item-base | E14: v1, v5 | F14: Sinto a necessidade de demonstrar um desempenho acadêmico/laboral superior ao dos outros para ter o meu valor reconhecido. | W14: =IF(COUNT(H14:L14)<Instruções!$B$5,"",AVERAGE(H14:L14)/Instruções!$B$6-Instruções!$B$7) | X14: =IF(COUNT(M14:Q14)<Instruções!$B$5,"",AVERAGE(M14:Q14)/Instruções!$B$6-Instruções!$B$7) | Y14: =IF(COUNT(R14:V14)<Instruções!$B$5,"",AVERAGE(R14:V14)/Instruções!$B$6-Instruções!$B$7) | Z14: =IF(OR(W14="",X14="",Y14=""),"",AVERAGE(W14:Y14)) | AA14: =IF(Z14="","",IF(Z14>=Instruções!$B$8,"Manter",IF(Z14>=Instruções!$B$9,"Revisar","Descartar")))
A15: D1-09 | B15: D1 | C15: B03 | D15: Variante do item-base | E15: v2 | F15: Sinto a exigência de entregar um desempenho superior para ter meu trabalho devidamente reconhecido na instituição. | W15: =IF(COUNT(H15:L15)<Instruções!$B$5,"",AVERAGE(H15:L15)/Instruções!$B$6-Instruções!$B$7) | X15: =IF(COUNT(M15:Q15)<Instruções!$B$5,"",AVERAGE(M15:Q15)/Instruções!$B$6-Instruções!$B$7) | Y15: =IF(COUNT(R15:V15)<Instruções!$B$5,"",AVERAGE(R15:V15)/Instruções!$B$6-Instruções!$B$7) | Z15: =IF(OR(W15="",X15="",Y15=""),"",AVERAGE(W15:Y15)) | AA15: =IF(Z15="","",IF(Z15>=Instruções!$B$8,"Manter",IF(Z15>=Instruções!$B$9,"Revisar","Descartar")))
A16: D1-10 | B16: D1 | C16: B03 | D16: Variante do item-base | E16: v3 | F16: Sinto a necessidade de demonstrar um desempenho superior ao dos outros para ter o meu valor reconhecido no trabalho. | W16: =IF(COUNT(H16:L16)<Instruções!$B$5,"",AVERAGE(H16:L16)/Instruções!$B$6-Instruções!$B$7) | X16: =IF(COUNT(M16:Q16)<Instruções!$B$5,"",AVERAGE(M16:Q16)/Instruções!$B$6-Instruções!$B$7) | Y16: =IF(COUNT(R16:V16)<Instruções!$B$5,"",AVERAGE(R16:V16)/Instruções!$B$6-Instruções!$B$7) | Z16: =IF(OR(W16="",X16="",Y16=""),"",AVERAGE(W16:Y16)) | AA16: =IF(Z16="","",IF(Z16>=Instruções!$B$8,"Manter",IF(Z16>=Instruções!$B$9,"Revisar","Descartar")))
A17: D1-11 | B17: D1 | C17: B03 | D17: Variante do item-base | E17: v4 | F17: Sinto que preciso demonstrar constantemente minha competência no trabalho. | W17: =IF(COUNT(H17:L17)<Instruções!$B$5,"",AVERAGE(H17:L17)/Instruções!$B$6-Instruções!$B$7) | X17: =IF(COUNT(M17:Q17)<Instruções!$B$5,"",AVERAGE(M17:Q17)/Instruções!$B$6-Instruções!$B$7) | Y17: =IF(COUNT(R17:V17)<Instruções!$B$5,"",AVERAGE(R17:V17)/Instruções!$B$6-Instruções!$B$7) | Z17: =IF(OR(W17="",X17="",Y17=""),"",AVERAGE(W17:Y17)) | AA17: =IF(Z17="","",IF(Z17>=Instruções!$B$8,"Manter",IF(Z17>=Instruções!$B$9,"Revisar","Descartar")))
A18: D1-12 | B18: D1 | C18: B04 | D18: Item-base | E18: v1, v4, v5 | F18: Perco a concentração nas tarefas quando presencio ou escuto comentários preconceituosos velados no ambiente universitário. | W18: =IF(COUNT(H18:L18)<Instruções!$B$5,"",AVERAGE(H18:L18)/Instruções!$B$6-Instruções!$B$7) | X18: =IF(COUNT(M18:Q18)<Instruções!$B$5,"",AVERAGE(M18:Q18)/Instruções!$B$6-Instruções!$B$7) | Y18: =IF(COUNT(R18:V18)<Instruções!$B$5,"",AVERAGE(R18:V18)/Instruções!$B$6-Instruções!$B$7) | Z18: =IF(OR(W18="",X18="",Y18=""),"",AVERAGE(W18:Y18)) | AA18: =IF(Z18="","",IF(Z18>=Instruções!$B$8,"Manter",IF(Z18>=Instruções!$B$9,"Revisar","Descartar")))
... A42: D1-36 | B42: D1 | C42: — | D42: Item novo | E42: v5 | F42: Me sinto cansado(a) mentalmente antes mesmo de chegar no campus apenas por ter que me preparar psicologicamente para as interações sociais no ambiente. | W42: =IF(COUNT(H42:L42)<Instruções!$B$5,"",AVERAGE(H42:L42)/Instruções!$B$6-Instruções!$B$7) | X42: =IF(COUNT(M42:Q42)<Instruções!$B$5,"",AVERAGE(M42:Q42)/Instruções!$B$6-Instruções!$B$7) | Y42: =IF(COUNT(R42:V42)<Instruções!$B$5,"",AVERAGE(R42:V42)/Instruções!$B$6-Instruções!$B$7) | Z42: =IF(OR(W42="",X42="",Y42=""),"",AVERAGE(W42:Y42)) | AA42: =IF(Z42="","",IF(Z42>=Instruções!$B$8,"Manter",IF(Z42>=Instruções!$B$9,"Revisar","Descartar")))
A43: D2 — Carga Mental de Transposição de Barreiras Desgaste decorrente de barreiras arquitetônicas, econômicas e comunicacionais.
A44: D2-01 | B44: D2 | C44: B08 | D44: Item-base | E44: v1, v4, v5 | F44: Gasto energia e tempo significativos do meu dia tentando resolver pendências operacionais ou financeiras de permanência (como transporte, alimentação, bolsas ou acessibilidade). | W44: =IF(COUNT(H44:L44)<Instruções!$B$5,"",AVERAGE(H44:L44)/Instruções!$B$6-Instruções!$B$7) | X44: =IF(COUNT(M44:Q44)<Instruções!$B$5,"",AVERAGE(M44:Q44)/Instruções!$B$6-Instruções!$B$7) | Y44: =IF(COUNT(R44:V44)<Instruções!$B$5,"",AVERAGE(R44:V44)/Instruções!$B$6-Instruções!$B$7) | Z44: =IF(OR(W44="",X44="",Y44=""),"",AVERAGE(W44:Y44)) | AA44: =IF(Z44="","",IF(Z44>=Instruções!$B$8,"Manter",IF(Z44>=Instruções!$B$9,"Revisar","Descartar")))
A45: D2-02 | B45: D2 | C45: B08 | D45: Variante do item-base | E45: v3 | F45: Consumo boa parte do meu dia e da minha energia lidando com a correria para me manter no trabalho, resolvendo problemas com transporte, alimentação e o dinheiro do mês. | W45: =IF(COUNT(H45:L45)<Instruções!$B$5,"",AVERAGE(H45:L45)/Instruções!$B$6-Instruções!$B$7) | X45: =IF(COUNT(M45:Q45)<Instruções!$B$5,"",AVERAGE(M45:Q45)/Instruções!$B$6-Instruções!$B$7) | Y45: =IF(COUNT(R45:V45)<Instruções!$B$5,"",AVERAGE(R45:V45)/Instruções!$B$6-Instruções!$B$7) | Z45: =IF(OR(W45="",X45="",Y45=""),"",AVERAGE(W45:Y45)) | AA45: =IF(Z45="","",IF(Z45>=Instruções!$B$8,"Manter",IF(Z45>=Instruções!$B$9,"Revisar","Descartar")))
A46: D2-03 | B46: D2 | C46: B09 | D46: Item-base | E46: v1, v4, v5 | F46: Sinto-me exausto(a) mentalmente por ter que negociar ou cobrar repetidamente por adaptações ou direitos básicos para conseguir estudar/trabalhar. | W46: =IF(COUNT(H46:L46)<Instruções!$B$5,"",AVERAGE(H46:L46)/Instruções!$B$6-Instruções!$B$7) | X46: =IF(COUNT(M46:Q46)<Instruções!$B$5,"",AVERAGE(M46:Q46)/Instruções!$B$6-Instruções!$B$7) | Y46: =IF(COUNT(R46:V46)<Instruções!$B$5,"",AVERAGE(R46:V46)/Instruções!$B$6-Instruções!$B$7) | Z46: =IF(OR(W46="",X46="",Y46=""),"",AVERAGE(W46:Y46)) | AA46: =IF(Z46="","",IF(Z46>=Instruções!$B$8,"Manter",IF(Z46>=Instruções!$B$9,"Revisar","Descartar")))
A47: D2-04 | B47: D2 | C47: B09 | D47: Variante do item-base | E47: v3 | F47: Sinto-me exausto(a) mentalmente por ter que negociar ou cobrar repetidamente por adaptações ou direitos básicos para conseguir trabalhar. | W47: =IF(COUNT(H47:L47)<Instruções!$B$5,"",AVERAGE(H47:L47)/Instruções!$B$6-Instruções!$B$7) | X47: =IF(COUNT(M47:Q47)<Instruções!$B$5,"",AVERAGE(M47:Q47)/Instruções!$B$6-Instruções!$B$7) | Y47: =IF(COUNT(R47:V47)<Instruções!$B$5,"",AVERAGE(R47:V47)/Instruções!$B$6-Instruções!$B$7) | Z47: =IF(OR(W47="",X47="",Y47=""),"",AVERAGE(W47:Y47)) | AA47: =IF(Z47="","",IF(Z47>=Instruções!$B$8,"Manter",IF(Z47>=Instruções!$B$9,"Revisar","Descartar")))
A48: D2-05 | B48: D2 | C48: B10 | D48: Item-base | E48: v1, v4, v5 | F48: Deixo de participar de atividades acadêmicas ou de lazer no campus por falta de recursos financeiros ou por barreiras de acessibilidade. | W48: =IF(COUNT(H48:L48)<Instruções!$B$5,"",AVERAGE(H48:L48)/Instruções!$B$6-Instruções!$B$7) | X48: =IF(COUNT(M48:Q48)<Instruções!$B$5,"",AVERAGE(M48:Q48)/Instruções!$B$6-Instruções!$B$7) | Y48: =IF(COUNT(R48:V48)<Instruções!$B$5,"",AVERAGE(R48:V48)/Instruções!$B$6-Instruções!$B$7) | Z48: =IF(OR(W48="",X48="",Y48=""),"",AVERAGE(W48:Y48)) | AA48: =IF(Z48="","",IF(Z48>=Instruções!$B$8,"Manter",IF(Z48>=Instruções!$B$9,"Revisar","Descartar")))
A49: D2-06 | B49: D2 | C49: B10 | D49: Variante do item-base | E49: v3 | F49: Deixo de ir a eventos, momentos de descanso ou atividades no trabalho por falta de dinheiro ou por dificuldade para me deslocar. | W49: =IF(COUNT(H49:L49)<Instruções!$B$5,"",AVERAGE(H49:L49)/Instruções!$B$6-Instruções!$B$7) | X49: =IF(COUNT(M49:Q49)<Instruções!$B$5,"",AVERAGE(M49:Q49)/Instruções!$B$6-Instruções!$B$7) | Y49: =IF(COUNT(R49:V49)<Instruções!$B$5,"",AVERAGE(R49:V49)/Instruções!$B$6-Instruções!$B$7) | Z49: =IF(OR(W49="",X49="",Y49=""),"",AVERAGE(W49:Y49)) | AA49: =IF(Z49="","",IF(Z49>=Instruções!$B$8,"Manter",IF(Z49>=Instruções!$B$9,"Revisar","Descartar")))
A50: D2-07 | B50: D2 | C50: B11 | D50: Item-base | E50: v1 | F50: Tenho dificuldades para dormir ou relaxar devido à preocupação constante com a minha continuidade na universidade. | W50: =IF(COUNT(H50:L50)<Instruções!$B$5,"",AVERAGE(H50:L50)/Instruções!$B$6-Instruções!$B$7) | X50: =IF(COUNT(M50:Q50)<Instruções!$B$5,"",AVERAGE(M50:Q50)/Instruções!$B$6-Instruções!$B$7) | Y50: =IF(COUNT(R50:V50)<Instruções!$B$5,"",AVERAGE(R50:V50)/Instruções!$B$6-Instruções!$B$7) | Z50: =IF(OR(W50="",X50="",Y50=""),"",AVERAGE(W50:Y50)) | AA50: =IF(Z50="","",IF(Z50>=Instruções!$B$8,"Manter",IF(Z50>=Instruções!$B$9,"Revisar","Descartar")))
A51: D2-08 | B51: D2 | C51: B11 | D51: Variante do item-base | E51: v3, v4 | F51: Tenho dificuldades para dormir ou relaxar devido à preocupação constante com a minha continuidade no trabalho. | W51: =IF(COUNT(H51:L51)<Instruções!$B$5,"",AVERAGE(H51:L51)/Instruções!$B$6-Instruções!$B$7) | X51: =IF(COUNT(M51:Q51)<Instruções!$B$5,"",AVERAGE(M51:Q51)/Instruções!$B$6-Instruções!$B$7) | Y51: =IF(COUNT(R51:V51)<Instruções!$B$5,"",AVERAGE(R51:V51)/Instruções!$B$6-Instruções!$B$7) | Z51: =IF(OR(W51="",X51="",Y51=""),"",AVERAGE(W51:Y51)) | AA51: =IF(Z51="","",IF(Z51>=Instruções!$B$8,"Manter",IF(Z51>=Instruções!$B$9,"Revisar","Descartar")))
A52: D2-09 | B52: D2 | C52: B11 | D52: Variante do item-base | E52: v5 | F52: Tenho dificuldades para dormir ou relaxar devido à preocupação constante com a minha continuidade acadêmica ou por medo de ser demitida. | W52: =IF(COUNT(H52:L52)<Instruções!$B$5,"",AVERAGE(H52:L52)/Instruções!$B$6-Instruções!$B$7) | X52: =IF(COUNT(M52:Q52)<Instruções!$B$5,"",AVERAGE(M52:Q52)/Instruções!$B$6-Instruções!$B$7) | Y52: =IF(COUNT(R52:V52)<Instruções!$B$5,"",AVERAGE(R52:V52)/Instruções!$B$6-Instruções!$B$7) | Z52: =IF(OR(W52="",X52="",Y52=""),"",AVERAGE(W52:Y52)) | AA52: =IF(Z52="","",IF(Z52>=Instruções!$B$8,"Manter",IF(Z52>=Instruções!$B$9,"Revisar","Descartar")))
A53: D2-10 | B53: D2 | C53: B12 | D53: Item-base | E53: v1, v5 | F53: Sinto que o desgaste para superar as barreiras de infraestrutura ou rotina da universidade prejudica minha saúde física ou mental. | W53: =IF(COUNT(H53:L53)<Instruções!$B$5,"",AVERAGE(H53:L53)/Instruções!$B$6-Instruções!$B$7) | X53: =IF(COUNT(M53:Q53)<Instruções!$B$5,"",AVERAGE(M53:Q53)/Instruções!$B$6-Instruções!$B$7) | Y53: =IF(COUNT(R53:V53)<Instruções!$B$5,"",AVERAGE(R53:V53)/Instruções!$B$6-Instruções!$B$7) | Z53: =IF(OR(W53="",X53="",Y53=""),"",AVERAGE(W53:Y53)) | AA53: =IF(Z53="","",IF(Z53>=Instruções!$B$8,"Manter",IF(Z53>=Instruções!$B$9,"Revisar","Descartar")))
A54: D2-11 | B54: D2 | C54: B12 | D54: Variante do item-base | E54: v3, v4 | F54: Sinto que o desgaste para superar as barreiras de infraestrutura ou rotina do trabalho prejudica minha saúde física ou mental. | W54: =IF(COUNT(H54:L54)<Instruções!$B$5,"",AVERAGE(H54:L54)/Instruções!$B$6-Instruções!$B$7) | X54: =IF(COUNT(M54:Q54)<Instruções!$B$5,"",AVERAGE(M54:Q54)/Instruções!$B$6-Instruções!$B$7) | Y54: =IF(COUNT(R54:V54)<Instruções!$B$5,"",AVERAGE(R54:V54)/Instruções!$B$6-Instruções!$B$7) | Z54: =IF(OR(W54="",X54="",Y54=""),"",AVERAGE(W54:Y54)) | AA54: =IF(Z54="","",IF(Z54>=Instruções!$B$8,"Manter",IF(Z54>=Instruções!$B$9,"Revisar","Descartar")))
A55: D2-12 | B55: D2 | C55: B13 | D55: Item-base | E55: v1, v5 | F55: Sinto-me fisicamente e mentalmente exausto(a) no final do dia devido ao esforço de locomoção ou falta de acessibilidade adequada no campus. | W55: =IF(COUNT(H55:L55)<Instruções!$B$5,"",AVERAGE(H55:L55)/Instruções!$B$6-Instruções!$B$7) | X55: =IF(COUNT(M55:Q55)<Instruções!$B$5,"",AVERAGE(M55:Q55)/Instruções!$B$6-Instruções!$B$7) | Y55: =IF(COUNT(R55:V55)<Instruções!$B$5,"",AVERAGE(R55:V55)/Instruções!$B$6-Instruções!$B$7) | Z55: =IF(OR(W55="",X55="",Y55=""),"",AVERAGE(W55:Y55)) | AA55: =IF(Z55="","",IF(Z55>=Instruções!$B$8,"Manter",IF(Z55>=Instruções!$B$9,"Revisar","Descartar")))
... A81: D2-38 | B81: D2 | C81: — | D81: Item novo | E81: v5 | F81: Sinto dores ou desconfortos físicos no corpo que associo ao esforço para realizar as tarefas e com a falta de equipamentos corretos. | W81: =IF(COUNT(H81:L81)<Instruções!$B$5,"",AVERAGE(H81:L81)/Instruções!$B$6-Instruções!$B$7) | X81: =IF(COUNT(M81:Q81)<Instruções!$B$5,"",AVERAGE(M81:Q81)/Instruções!$B$6-Instruções!$B$7) | Y81: =IF(COUNT(R81:V81)<Instruções!$B$5,"",AVERAGE(R81:V81)/Instruções!$B$6-Instruções!$B$7) | Z81: =IF(OR(W81="",X81="",Y81=""),"",AVERAGE(W81:Y81)) | AA81: =IF(Z81="","",IF(Z81>=Instruções!$B$8,"Manter",IF(Z81>=Instruções!$B$9,"Revisar","Descartar")))
A82: D3 — Agência Comunitária e Rede de Cuidado Solidário Fatores de proteção e suporte social interpessoal no campus.
A83: D3-01 | B83: D3 | C83: B15 | D83: Item-base | E83: v1, v4, v5 | F83: Encontro apoio e acolhimento em colegas ou coletivos dentro do campus quando me sinto sobrecarregado(a). | W83: =IF(COUNT(H83:L83)<Instruções!$B$5,"",AVERAGE(H83:L83)/Instruções!$B$6-Instruções!$B$7) | X83: =IF(COUNT(M83:Q83)<Instruções!$B$5,"",AVERAGE(M83:Q83)/Instruções!$B$6-Instruções!$B$7) | Y83: =IF(COUNT(R83:V83)<Instruções!$B$5,"",AVERAGE(R83:V83)/Instruções!$B$6-Instruções!$B$7) | Z83: =IF(OR(W83="",X83="",Y83=""),"",AVERAGE(W83:Y83)) | AA83: =IF(Z83="","",IF(Z83>=Instruções!$B$8,"Manter",IF(Z83>=Instruções!$B$9,"Revisar","Descartar")))
A84: D3-02 | B84: D3 | C84: B15 | D84: Variante do item-base | E84: v2 | F84: Encontro apoio e acolhimento em colegas, equipes ou coletivos no campus diante de situações de sobrecarga. | W84: =IF(COUNT(H84:L84)<Instruções!$B$5,"",AVERAGE(H84:L84)/Instruções!$B$6-Instruções!$B$7) | X84: =IF(COUNT(M84:Q84)<Instruções!$B$5,"",AVERAGE(M84:Q84)/Instruções!$B$6-Instruções!$B$7) | Y84: =IF(COUNT(R84:V84)<Instruções!$B$5,"",AVERAGE(R84:V84)/Instruções!$B$6-Instruções!$B$7) | Z84: =IF(OR(W84="",X84="",Y84=""),"",AVERAGE(W84:Y84)) | AA84: =IF(Z84="","",IF(Z84>=Instruções!$B$8,"Manter",IF(Z84>=Instruções!$B$9,"Revisar","Descartar")))
A85: D3-03 | B85: D3 | C85: B15 | D85: Variante do item-base | E85: v3 | F85: Encontro apoio e acolhimento em colegas ou coletivos dentro do trabalho quando me sinto sobrecarregado(a). | W85: =IF(COUNT(H85:L85)<Instruções!$B$5,"",AVERAGE(H85:L85)/Instruções!$B$6-Instruções!$B$7) | X85: =IF(COUNT(M85:Q85)<Instruções!$B$5,"",AVERAGE(M85:Q85)/Instruções!$B$6-Instruções!$B$7) | Y85: =IF(COUNT(R85:V85)<Instruções!$B$5,"",AVERAGE(R85:V85)/Instruções!$B$6-Instruções!$B$7) | Z85: =IF(OR(W85="",X85="",Y85=""),"",AVERAGE(W85:Y85)) | AA85: =IF(Z85="","",IF(Z85>=Instruções!$B$8,"Manter",IF(Z85>=Instruções!$B$9,"Revisar","Descartar")))
A86: D3-04 | B86: D3 | C86: B16 | D86: Item-base | E86: v1, v3, v4, v5 | F86: Consigo conversar abertamente com pessoas da universidade sobre as dificuldades que enfrento no meu dia a dia. | W86: =IF(COUNT(H86:L86)<Instruções!$B$5,"",AVERAGE(H86:L86)/Instruções!$B$6-Instruções!$B$7) | X86: =IF(COUNT(M86:Q86)<Instruções!$B$5,"",AVERAGE(M86:Q86)/Instruções!$B$6-Instruções!$B$7) | Y86: =IF(COUNT(R86:V86)<Instruções!$B$5,"",AVERAGE(R86:V86)/Instruções!$B$6-Instruções!$B$7) | Z86: =IF(OR(W86="",X86="",Y86=""),"",AVERAGE(W86:Y86)) | AA86: =IF(Z86="","",IF(Z86>=Instruções!$B$8,"Manter",IF(Z86>=Instruções!$B$9,"Revisar","Descartar")))
A87: D3-05 | B87: D3 | C87: B16 | D87: Variante do item-base | E87: v2 | F87: Identifico abertura para conversar sobre as dificuldades do meu cotidiano com pessoas da comunidade universitária. | W87: =IF(COUNT(H87:L87)<Instruções!$B$5,"",AVERAGE(H87:L87)/Instruções!$B$6-Instruções!$B$7) | X87: =IF(COUNT(M87:Q87)<Instruções!$B$5,"",AVERAGE(M87:Q87)/Instruções!$B$6-Instruções!$B$7) | Y87: =IF(COUNT(R87:V87)<Instruções!$B$5,"",AVERAGE(R87:V87)/Instruções!$B$6-Instruções!$B$7) | Z87: =IF(OR(W87="",X87="",Y87=""),"",AVERAGE(W87:Y87)) | AA87: =IF(Z87="","",IF(Z87>=Instruções!$B$8,"Manter",IF(Z87>=Instruções!$B$9,"Revisar","Descartar")))
A88: D3-06 | B88: D3 | C88: B17 | D88: Item-base | E88: v1, v3, v4, v5 | F88: Participo de espaços ou redes de apoio mútuo que me ajudam a manter a motivação para continuar na instituição. | W88: =IF(COUNT(H88:L88)<Instruções!$B$5,"",AVERAGE(H88:L88)/Instruções!$B$6-Instruções!$B$7) | X88: =IF(COUNT(M88:Q88)<Instruções!$B$5,"",AVERAGE(M88:Q88)/Instruções!$B$6-Instruções!$B$7) | Y88: =IF(COUNT(R88:V88)<Instruções!$B$5,"",AVERAGE(R88:V88)/Instruções!$B$6-Instruções!$B$7) | Z88: =IF(OR(W88="",X88="",Y88=""),"",AVERAGE(W88:Y88)) | AA88: =IF(Z88="","",IF(Z88>=Instruções!$B$8,"Manter",IF(Z88>=Instruções!$B$9,"Revisar","Descartar")))
...

Sheet Resumo
A1: Resumo do CVC por dimensão
A3: Dim. | B3: Nº de itens | C3: Itens avaliados (5 juízes) | D3: CVC clareza | E3: CVC pertinência | F3: CVC relevância | G3: CVC da dimensão | H3: Manter | I3: Revisar | J3: Descartar
A4: D1 | B4: =COUNTIF('Avaliação CVC'!$B$6:$B$165,A4) -> 36 | C4: =COUNTIFS('Avaliação CVC'!$B$6:$B$165,A4,'Avaliação CVC'!$Z$6:$Z$165,">-1") -> 0 | D4: =IFERROR(AVERAGEIFS('Avaliação CVC'!$W$6:$W$165,'Avaliação CVC'!$B$6:$B$165,A4),"") | E4: =IFERROR(AVERAGEIFS('Avaliação CVC'!$X$6:$X$165,'Avaliação CVC'!$B$6:$B$165,A4),"") | F4: =IFERROR(AVERAGEIFS('Avaliação CVC'!$Y$6:$Y$165,'Avaliação CVC'!$B$6:$B$165,A4),"") | G4: =IFERROR(AVERAGEIFS('Avaliação CVC'!$Z$6:$Z$165,'Avaliação CVC'!$B$6:$B$165,A4),"") | H4: =COUNTIFS('Avaliação CVC'!$B$6:$B$165,A4,'Avaliação CVC'!$AA$6:$AA$165,"Manter") -> 0 | I4: =COUNTIFS('Avaliação CVC'!$B$6:$B$165,A4,'Avaliação CVC'!$AA$6:$AA$165,"Revisar") -> 0 | J4: =COUNTIFS('Avaliação CVC'!$B$6:$B$165,A4,'Avaliação CVC'!$AA$6:$AA$165,"Descartar") -> 0
A5: D2 | B5: =COUNTIF('Avaliação CVC'!$B$6:$B$165,A5) -> 38 | C5: =COUNTIFS('Avaliação CVC'!$B$6:$B$165,A5,'Avaliação CVC'!$Z$6:$Z$165,">-1") -> 0 | D5: =IFERROR(AVERAGEIFS('Avaliação CVC'!$W$6:$W$165,'Avaliação CVC'!$B$6:$B$165,A5),"") | E5: =IFERROR(AVERAGEIFS('Avaliação CVC'!$X$6:$X$165,'Avaliação CVC'!$B$6:$B$165,A5),"") | F5: =IFERROR(AVERAGEIFS('Avaliação CVC'!$Y$6:$Y$165,'Avaliação CVC'!$B$6:$B$165,A5),"") | G5: =IFERROR(AVERAGEIFS('Avaliação CVC'!$Z$6:$Z$165,'Avaliação CVC'!$B$6:$B$165,A5),"") | H5: =COUNTIFS('Avaliação CVC'!$B$6:$B$165,A5,'Avaliação CVC'!$AA$6:$AA$165,"Manter") -> 0 | I5: =COUNTIFS('Avaliação CVC'!$B$6:$B$165,A5,'Avaliação CVC'!$AA$6:$AA$165,"Revisar") -> 0 | J5: =COUNTIFS('Avaliação CVC'!$B$6:$B$165,A5,'Avaliação CVC'!$AA$6:$AA$165,"Descartar") -> 0
A6: D3 | B6: =COUNTIF('Avaliação CVC'!$B$6:$B$165,A6) -> 35 | C6: =COUNTIFS('Avaliação CVC'!$B$6:$B$165,A6,'Avaliação CVC'!$Z$6:$Z$165,">-1") -> 0 | D6: =IFERROR(AVERAGEIFS('Avaliação CVC'!$W$6:$W$165,'Avaliação CVC'!$B$6:$B$165,A6),"") | E6: =IFERROR(AVERAGEIFS('Avaliação CVC'!$X$6:$X$165,'Avaliação CVC'!$B$6:$B$165,A6),"") | F6: =IFERROR(AVERAGEIFS('Avaliação CVC'!$Y$6:$Y$165,'Avaliação CVC'!$B$6:$B$165,A6),"") | G6: =IFERROR(AVERAGEIFS('Avaliação CVC'!$Z$6:$Z$165,'Avaliação CVC'!$B$6:$B$165,A6),"") | H6: =COUNTIFS('Avaliação CVC'!$B$6:$B$165,A6,'Avaliação CVC'!$AA$6:$AA$165,"Manter") -> 0 | I6: =COUNTIFS('Avaliação CVC'!$B$6:$B$165,A6,'Avaliação CVC'!$AA$6:$AA$165,"Revisar") -> 0 | J6: =COUNTIFS('Avaliação CVC'!$B$6:$B$165,A6,'Avaliação CVC'!$AA$6:$AA$165,"Descartar") -> 0
A7: D4 | B7: =COUNTIF('Avaliação CVC'!$B$6:$B$165,A7) -> 37 | C7: =COUNTIFS('Avaliação CVC'!$B$6:$B$165,A7,'Avaliação CVC'!$Z$6:$Z$165,">-1") -> 0 | D7: =IFERROR(AVERAGEIFS('Avaliação CVC'!$W$6:$W$165,'Avaliação CVC'!$B$6:$B$165,A7),"") | E7: =IFERROR(AVERAGEIFS('Avaliação CVC'!$X$6:$X$165,'Avaliação CVC'!$B$6:$B$165,A7),"") | F7: =IFERROR(AVERAGEIFS('Avaliação CVC'!$Y$6:$Y$165,'Avaliação CVC'!$B$6:$B$165,A7),"") | G7: =IFERROR(AVERAGEIFS('Avaliação CVC'!$Z$6:$Z$165,'Avaliação CVC'!$B$6:$B$165,A7),"") | H7: =COUNTIFS('Avaliação CVC'!$B$6:$B$165,A7,'Avaliação CVC'!$AA$6:$AA$165,"Manter") -> 0 | I7: =COUNTIFS('Avaliação CVC'!$B$6:$B$165,A7,'Avaliação CVC'!$AA$6:$AA$165,"Revisar") -> 0 | J7: =COUNTIFS('Avaliação CVC'!$B$6:$B$165,A7,'Avaliação CVC'!$AA$6:$AA$165,"Descartar") -> 0
A8: D5 | B8: =COUNTIF('Avaliação CVC'!$B$6:$B$165,A8) -> 9 | C8: =COUNTIFS('Avaliação CVC'!$B$6:$B$165,A8,'Avaliação CVC'!$Z$6:$Z$165,">-1") -> 0 | D8: =IFERROR(AVERAGEIFS('Avaliação CVC'!$W$6:$W$165,'Avaliação CVC'!$B$6:$B$165,A8),"") | E8: =IFERROR(AVERAGEIFS('Avaliação CVC'!$X$6:$X$165,'Avaliação CVC'!$B$6:$B$165,A8),"") | F8: =IFERROR(AVERAGEIFS('Avaliação CVC'!$Y$6:$Y$165,'Avaliação CVC'!$B$6:$B$165,A8),"") | G8: =IFERROR(AVERAGEIFS('Avaliação CVC'!$Z$6:$Z$165,'Avaliação CVC'!$B$6:$B$165,A8),"") | H8: =COUNTIFS('Avaliação CVC'!$B$6:$B$165,A8,'Avaliação CVC'!$AA$6:$AA$165,"Manter") -> 0 | I8: =COUNTIFS('Avaliação CVC'!$B$6:$B$165,A8,'Avaliação CVC'!$AA$6:$AA$165,"Revisar") -> 0 | J8: =COUNTIFS('Avaliação CVC'!$B$6:$B$165,A8,'Avaliação CVC'!$AA$6:$AA$165,"Descartar") -> 0
A9: Total | B9: =SUM(B4:B8) -> 155 | C9: =SUM(C4:C8) -> 0 | D9: =IFERROR(AVERAGE('Avaliação CVC'!$W$6:$W$165),"") | E9: =IFERROR(AVERAGE('Avaliação CVC'!$X$6:$X$165),"") | F9: =IFERROR(AVERAGE('Avaliação CVC'!$Y$6:$Y$165),"") | G9: =IFERROR(AVERAGE('Avaliação CVC'!$Z$6:$Z$165),"") | H9: =SUM(H4:H8) -> 0 | I9: =SUM(I4:I8) -> 0 | J9: =SUM(J4:J8) -> 0
A11: Itens únicos por dimensão e versão de origem (um item idêntico em várias versões conta em cada uma)
A12: Dim. | B12: v1 | C12: v2 | D12: v3 | E12: v4 | F12: v5
A13: D1 | B13: =COUNTIFS('Avaliação CVC'!$B$6:$B$165,$A13,'Avaliação CVC'!$E$6:$E$165,"*v1*") -> 11 | C13: =COUNTIFS('Avaliação CVC'!$B$6:$B$165,$A13,'Avaliação CVC'!$E$6:$E$165,"*v2*") -> 8 | D13: =COUNTIFS('Avaliação CVC'!$B$6:$B$165,$A13,'Avaliação CVC'!$E$6:$E$165,"*v3*") -> 10 | E13: =COUNTIFS('Avaliação CVC'!$B$6:$B$165,$A13,'Avaliação CVC'!$E$6:$E$165,"*v4*") -> 10 | F13: =COUNTIFS('Avaliação CVC'!$B$6:$B$165,$A13,'Avaliação CVC'!$E$6:$E$165,"*v5*") -> 10
A14: D2 | B14: =COUNTIFS('Avaliação CVC'!$B$6:$B$165,$A14,'Avaliação CVC'!$E$6:$E$165,"*v1*") -> 10 | C14: =COUNTIFS('Avaliação CVC'!$B$6:$B$165,$A14,'Avaliação CVC'!$E$6:$E$165,"*v2*") -> 9 | D14: =COUNTIFS('Avaliação CVC'!$B$6:$B$165,$A14,'Avaliação CVC'!$E$6:$E$165,"*v3*") -> 10 | E14: =COUNTIFS('Avaliação CVC'!$B$6:$B$165,$A14,'Avaliação CVC'!$E$6:$E$165,"*v4*") -> 10 | F14: =COUNTIFS('Avaliação CVC'!$B$6:$B$165,$A14,'Avaliação CVC'!$E$6:$E$165,"*v5*") -> 10
A15: D3 | B15: =COUNTIFS('Avaliação CVC'!$B$6:$B$165,$A15,'Avaliação CVC'!$E$6:$E$165,"*v1*") -> 10 | C15: =COUNTIFS('Avaliação CVC'!$B$6:$B$165,$A15,'Avaliação CVC'!$E$6:$E$165,"*v2*") -> 9 | D15: =COUNTIFS('Avaliação CVC'!$B$6:$B$165,$A15,'Avaliação CVC'!$E$6:$E$165,"*v3*") -> 10 | E15: =COUNTIFS('Avaliação CVC'!$B$6:$B$165,$A15,'Avaliação CVC'!$E$6:$E$165,"*v4*") -> 10 | F15: =COUNTIFS('Avaliação CVC'!$B$6:$B$165,$A15,'Avaliação CVC'!$E$6:$E$165,"*v5*") -> 10
A16: D4 | B16: =COUNTIFS('Avaliação CVC'!$B$6:$B$165,$A16,'Avaliação CVC'!$E$6:$E$165,"*v1*") -> 10 | C16: =COUNTIFS('Avaliação CVC'!$B$6:$B$165,$A16,'Avaliação CVC'!$E$6:$E$165,"*v2*") -> 9 | D16: =COUNTIFS('Avaliação CVC'!$B$6:$B$165,$A16,'Avaliação CVC'!$E$6:$E$165,"*v3*") -> 10 | E16: =COUNTIFS('Avaliação CVC'!$B$6:$B$165,$A16,'Avaliação CVC'!$E$6:$E$165,"*v4*") -> 10 | F16: =COUNTIFS('Avaliação CVC'!$B$6:$B$165,$A16,'Avaliação CVC'!$E$6:$E$165,"*v5*") -> 10
A17: D5 | B17: =COUNTIFS('Avaliação CVC'!$B$6:$B$165,$A17,'Avaliação CVC'!$E$6:$E$165,"*v1*") -> 0 | C17: =COUNTIFS('Avaliação CVC'!$B$6:$B$165,$A17,'Avaliação CVC'!$E$6:$E$165,"*v2*") -> 9 | D17: =COUNTIFS('Avaliação CVC'!$B$6:$B$165,$A17,'Avaliação CVC'!$E$6:$E$165,"*v3*") -> 0 | E17: =COUNTIFS('Avaliação CVC'!$B$6:$B$165,$A17,'Avaliação CVC'!$E$6:$E$165,"*v4*") -> 0 | F17: =COUNTIFS('Avaliação CVC'!$B$6:$B$165,$A17,'Avaliação CVC'!$E$6:$E$165,"*v5*") -> 0
A18: Total | B18: =SUM(B13:B17) -> 41 | C18: =SUM(C13:C17) -> 44 | D18: =SUM(D13:D17) -> 40 | E18: =SUM(E13:E17) -> 40 | F18: =SUM(F13:F17) -> 40
A20: Conferência: os totais por versão (41, 44, 40, 40, 40) batem com o arquivo build_corpus_correction.py.
